{"messageId":"43b634ca-903f-47bb-8ef9-5ceb9f1b04bd","message":"0 : Stack error (CREATE_FAILED): Resource CREATE failed: Exception: resources.network: HTTP Status: 500 Content: <pre>Traceback (most recent call last):\n  File \"/usr/lib/python2.7/dist-packages/vnc_cfg_api_server/vnc_cfg_api_server.py\", line 622, in http_resource_create\n    ok, result = stateful_create()\n  File \"/usr/lib/python2.7/dist-packages/vnc_cfg_api_server/vnc_cfg_api_server.py\", line 566, in stateful_create\n    tenant_name, obj_dict, db_conn)\n  File \"/usr/lib/python2.7/dist-packages/vnc_cfg_api_server/vnc_cfg_types.py\", line 1463, in pre_dbe_create\n    vn_uuid)\n  File \"/usr/lib/python2.7/dist-packages/vnc_cfg_api_server/vnc_cfg_types.py\", line 1396, in _check_ipam_network_subnets\n    (ok, result) = cls.addr_mgmt.net_check_subnet(ipam_subnets)\n  File \"/usr/lib/python2.7/dist-packages/vnc_cfg_api_server/vnc_addr_mgmt.py\", line 987, in net_check_subnet\n    network = IPNetwork('%s/%s' % (prefix, prefix_len))\n  File \"/usr/lib/python2.7/dist-packages/netaddr/ip/__init__.py\", line 933, in __init__\n    raise AddrFormatError('invalid IPNetwork %s' % addr)\nAddrFormatError: invalid IPNetwork /0\n</pre>\n","category":"INTERNAL","rolledBack":true}
